func_1
func_2
func_3
Doing something bad...


Terminating due to an unhandled exception.

  throw std::out_of_range(...);
  ^~~~~~~~~~~~~~~~~~~~~~~~~~~~~ basic_string::at: __n (which is 1) >= this->size() (which is 0)


Stack trace:

  0 0x1041b8b68 tit::TerminateHandler::handle_terminate_()
  1 0x1045868cc __cxxabiv1::__terminate(void (*)())
  2 0x10469bdbc std::unexpected()
  3 0x104586bc0 __cxa_rethrow
  4 0x10469c20c std::__throw_out_of_range_fmt(char const*, ...)
  5 0x1041e1fb4 tit::(anonymous namespace)::func_3()
  6 0x1041afe64 tit::(anonymous namespace)::func_1()
  7 0x1041afe88 tit::(anonymous namespace)::run_test(int, char**)
  8 0x1041afe94 tit::(anonymous namespace)::run_test(int, char**)
  9 0x1041b8d10 tit::run_main(int, char**, std::function<int (int, char**)> const&)
 10 0x1041e2398 main
