func_1
func_2
func_3
Doing something bad...


/Users/jhuighuy/TitSolver/source/tit/main/main.cpp:146:30: Terminating due to an unhandled exception.

Stack trace:

  0 0x104f139e0 tit::(anonymous namespace)::setup_terminate_handler()::{lambda()#1}::operator()() const [clone .constprop.0]
  1 0x104f13f34 tit::(anonymous namespace)::setup_terminate_handler()::{lambda()#1}::_FUN()
  2 0x105727aec __cxxabiv1::__terminate(void (*)())
  3 0x10583ba1c std::unexpected()
  4 0x105727dfc __cxa_throw
  5 0x104f12d80 tit::(anonymous namespace)::func_2()
  6 0x104f12da8 tit::(anonymous namespace)::func_1() [clone .lto_priv.0]
  7 0x104f12dd0 tit::(anonymous namespace)::func_1() [clone .lto_priv.0]
  8 0x104f6d2c4 main

terminate called after throwing an instance of 'unsigned int'
