func_1
func_2
func_3
Throwing an exception...


/Users/jhuighuy/TitSolver/tests/tit/core/catch_tit_exception.cpp:19:3: Terminating due to an unhandled exception.

  throw tit::Exception(...);
  ^~~~~~~~~~~~~~~~~~~~~~~~~~ Test exception, Some arguments: 13, hello.


Stack trace:

  0 0x1047ad644 tit::(anonymous namespace)::func_3()
  1 0x1047ad78c tit::(anonymous namespace)::func_1()
  2 0x1047ad7b0 tit::(anonymous namespace)::run_test(std::span<char const*, 18446744073709551615ul>)
  3 0x1047ad7bc tit::(anonymous namespace)::run_test(std::span<char const*, 18446744073709551615ul>)
  4 0x1047b6b44 tit::run_main(int, char**, std::function<int (std::span<char const*, 18446744073709551615ul>)> const&)
  5 0x1047fae18 main
